Workbook

Sheet Stop Coverage
A1: Stop / Landmark | B1: No. of Routes Serving | C1: Total Buses Passing | D1: Route Numbers
A2: ISBT-17 | B2: 47 | C2: 274 | D2: 1, 101, 11, 123A, 14, 17, 202, 206, 212, 214, 216, 219, 22, 239, 23B, 240, 24C, 25/25A, 26, 28, 28A, 2A, 2C, 2F, 30, 30B, 31, 32, 32B, 34, 35, 35A, 35B, 35D, 37, 38AB, 38B, 39, 40, 4C, 7, 70A, 71, 76, 79, 80, 85
A3: ISBT-43 | B3: 39 | C3: 224 | D3: 10, 101, 123A, 14, 17, 18, 20, 202, 206, 20A, 213, 216, 22, 239, 23A, 240, 241, 242, 24A, 24C, 28A, 28B, 30, 30A, 30B, 35B, 37, 38AB, 38B, 39, 4A, 4C, 551, 5A, 5C, 6, 71, 8, 85
A4: PGI | B4: 33 | C4: 188 | D4: 1, 101, 123A, 212, 214, 219, 23A, 23B, 242, 24A, 25/25A, 26, 28A, 2A, 2C, 2F, 2G, 31, 32, 32B, 34, 35A, 38B, 39, 40, 4A, 4C, 5A, 5C, 70A, 79, 8, 80
A5: Aroma | B5: 22 | C5: 128 | D5: 101, 123A, 17, 20, 20A, 216, 219, 239, 23A, 240, 242, 24A, 30, 30B, 35, 35B, 38AB, 7, 79, 8, 80, 85
A6: 23/22 | B6: 18 | C6: 100 | D6: 14, 17, 18, 202, 206, 216, 22, 240, 24C, 28, 28A, 30, 30B, 37, 39, 7, 71, 85
A7: PEC | B7: 16 | C7: 96 | D7: 101, 123A, 212, 214, 219, 23A, 242, 31, 34, 35A, 38B, 39, 551, 79, 8, 80
A8: New OPD | B8: 12 | C8: 80 | D8: 212, 23A, 242, 2F, 31, 32B, 34, 35A, 38B, 4C, 70A, 80
A9: Attawa | B9: 12 | C9: 67 | D9: 18, 206, 216, 24C, 28B, 30, 30A, 30B, 35, 37, 38B, 85
A10: 10/16 | B10: 10 | C10: 62 | D10: 101, 123A, 219, 26, 2C, 2F, 32B, 5C, 79, 80
A11: 7/19 | B11: 10 | C11: 71 | D11: 11, 206, 28, 2C, 2F, 2G, 31, 32, 32B, 5C
A12: Manimajra | B12: 9 | C12: 47 | D12: 1, 10, 28, 2A, 30, 37, 70A, 9A, 9C
A13: 8/18 | B13: 9 | C13: 57 | D13: 11, 206, 28, 2C, 2F, 2G, 31, 32B, 5C
... A650: New Airport | B650: 1 | C650: 8 | D650: 38AB
A652: Note: Stop names are taken verbatim from route descriptions (e.g. '22/17' vs '17/22' may refer to the same junction but appear as separate rows here). Treat this sheet as a first-pass coverage map, not a canonical stop registry.

Sheet Route Master
A1: Route No. | B1: Origin | C1: Destination | D1: Operating Hours | E1: Frequency (min) | F1: Freq Min | G1: Freq Max | H1: Route Length (km) | I1: No. of Buses Allocated | J1: No. of Via-Stops Listed
A2: 1 | B2: New Maloya Colony | C2: Manimajra | D2: 06.10-17.20 / 07.30-18.40 | E2: 20 | F2: 20 | G2: 20 | H2: 24 | I2: 8 | J2: 18
A3: 2A | B3: Manimajra | C3: Manimajra | D3: 05.40-20.30 | E3: 20-25 | F3: 20 | G3: 25 | H3: 38.3 | I3: 6 | J3: 31
A4: 2C | B4: Mani Majra | C4: Mani Majra | D4: 05.30-20.20 | E4: 20-25 | F4: 20 | G4: 25 | H4: 38.3 | I4: 6 | J4: 32
A5: 4A | B5: ISBT-43 | C5: ISBT-43 | D5: 06.45-19.40 | E5: 25 | F5: 25 | G5: 25 | H5: 32.5 | I5: 4 | J5: 24
A6: 4C | B6: ISBT-43 | C6: ISBT-43 | D6: 07.25-20.20 | E6: 25 | F6: 25 | G6: 25 | H6: 32.5 | I6: 4 | J6: 25
A7: 5A | B7: RamDarbar | C7: RamDarbar | D7: 05.25-21.00 | E7: 15-30 | F7: 15 | G7: 30 | H7: 38.4 | I7: 8 | J7: 29
A8: 5C | B8: Ram Darbar | C8: Ram Darbar | D8: 05.50-21.25 | E8: 15-30 | F8: 15 | G8: 30 | H8: 38.4 | I8: 8 | J8: 28
A9: 6 | B9: New Maloya Colony | C9: Raipur Kalan | D9: 05.00-17.10 / 06.30-18.40 | E9: 30 | F9: 30 | G9: 30 | H9: 25.5 | I9: 6 | J9: 18
A10: 7 | B10: New Maloya Colony | C10: Ramdarbar | D10: 05.45-18.40 / 07.00-17.25 | E10: 25 | F10: 25 | G10: 25 | H10: 21.5 | I10: 6 | J10: 18
A11: 9A | B11: Mansa Devi | C11: Mansa Devi | D11: 06.10-20.30 | E11: 30 | F11: 30 | G11: 30 | H11: 38.3 | I11: 4 | J11: 36
A12: 9C | B12: Mansa Devi | C12: Mansa Devi | D12: 05.40-20.45 | E12: 30 | F12: 30 | G12: 30 | H12: 38.3 | I12: 4 | J12: 37
A13: 11A | B13: Rock Garden | C13: Sukhna Lake | D13: 10:10-15.50 | E13: 30 | F13: 30 | G13: 30 | H13: 3 | I13: 1 | J13: 1
... A69: 38AB | B69: ISBT-17 | C69: New Airport | D69: 00.40-22.10 / 01.50-23.30 | E69: 20-25 | F69: 20 | G69: 25 | H69: 22 | I69: 8 | J69: 16
A70: TOTAL | H70: =SUM(H2:H69) -> 1662 | I70: =SUM(I2:I69) -> 389 | J70: =SUM(J2:J69) -> 1163

Sheet Model Variables
A1: OPTIMIZATION MODEL PARAMETERS — derived from Synopsis Section 3.1
A2: Sets: R = {68 routes below}, T = time period (not split — see note at bottom) | C2: Extra stop time at refuelling, 17, 43, railway, CTU not included
C3: assumed with avg speed 22km/hr | E3: least no of buses/hr | F3: max no of buses per hr | G3: AVERAGE(f_rt^min, f_rt^max) | H3: x_rt ÷ τ_r
A4: Route (r) | B4: d_r Route Distance (km) | C4: τ_r Cycle Time (hrs, ESTIMATED) | D4: x_rt Buses Allocated (baseline) | E4: f_rt^min (dep/hr) | F4: f_rt^max (dep/hr) | G4: f_rt Implied Frequency (dep/hr, midpoint) | H4: Max Feasible Frequency (x_rt / τ_r) | I4: D_rt Passenger Demand | J4: C Bus Capacity | K4: o_rt Overcrowding
A5: 1 | B5: 24 | C5: =B5/22 -> 1.0909091 | D5: 8 | E5: 3 | F5: 3 | G5: =AVERAGE(E5:F5) -> 3 | H5: =D5/C5 -> 7.3333333 | I5: NA | J5: NA | K5: NA
A6: 2A | B6: 38.3 | C6: =B6/22 -> 1.7409091 | D6: 6 | E6: 2.4 | F6: 3 | G6: =AVERAGE(E6:F6) -> 2.7 | H6: =D6/C6 -> 3.4464752 | I6: NA | J6: NA | K6: NA
A7: 2C | B7: 38.3 | C7: =B7/22 -> 1.7409091 | D7: 6 | E7: 2.4 | F7: 3 | G7: =AVERAGE(E7:F7) -> 2.7 | H7: =D7/C7 -> 3.4464752 | I7: NA | J7: NA | K7: NA
A8: 4A | B8: 32.5 | C8: =B8/22 -> 1.4772727 | D8: 4 | E8: 2.4 | F8: 2.4 | G8: =AVERAGE(E8:F8) -> 2.4 | H8: =D8/C8 -> 2.7076923 | I8: NA | J8: NA | K8: NA
A9: 4C | B9: 32.5 | C9: =B9/22 -> 1.4772727 | D9: 4 | E9: 2.4 | F9: 2.4 | G9: =AVERAGE(E9:F9) -> 2.4 | H9: =D9/C9 -> 2.7076923 | I9: NA | J9: NA | K9: NA
A10: 5A | B10: 38.4 | C10: =B10/22 -> 1.7454545 | D10: 8 | E10: 2 | F10: 4 | G10: =AVERAGE(E10:F10) -> 3 | H10: =D10/C10 -> 4.5833333 | I10: NA | J10: NA | K10: NA
A11: 5C | B11: 38.4 | C11: =B11/22 -> 1.7454545 | D11: 8 | E11: 2 | F11: 4 | G11: =AVERAGE(E11:F11) -> 3 | H11: =D11/C11 -> 4.5833333 | I11: NA | J11: NA | K11: NA
A12: 6 | B12: 25.5 | C12: =B12/22 -> 1.1590909 | D12: 6 | E12: 2 | F12: 2 | G12: =AVERAGE(E12:F12) -> 2 | H12: =D12/C12 -> 5.1764706 | I12: NA | J12: NA | K12: NA
A13: 7 | B13: 21.5 | C13: =B13/22 -> 0.97727273 | D13: 6 | E13: 2.4 | F13: 2.4 | G13: =AVERAGE(E13:F13) -> 2.4 | H13: =D13/C13 -> 6.1395349 | I13: NA | J13: NA | K13: NA
A14: 9A | B14: 38.3 | C14: =B14/22 -> 1.7409091 | D14: 4 | E14: 2 | F14: 2 | G14: =AVERAGE(E14:F14) -> 2 | H14: =D14/C14 -> 2.2976501 | I14: NA | J14: NA | K14: NA
A15: 9C | B15: 38.3 | C15: =B15/22 -> 1.7409091 | D15: 4 | E15: 2 | F15: 2 | G15: =AVERAGE(E15:F15) -> 2 | H15: =D15/C15 -> 2.2976501 | I15: NA | J15: NA | K15: NA
A16: 11A | B16: 3 | C16: =B16/22 -> 0.13636364 | D16: 1 | E16: 2 | F16: 2 | G16: =AVERAGE(E16:F16) -> 2 | H16: =D16/C16 -> 7.3333333 | I16: NA | J16: NA | K16: NA
... A72: 38AB | B72: 22 | C72: =B72/22 -> 1 | D72: 8 | E72: 2.4 | F72: 3 | G72: =AVERAGE(E72:F72) -> 2.7 | H72: =D72/C72 -> 8 | I72: NA | J72: NA | K72: NA
A74: B (Total Fleet Pool) | D74: =SUM(D5:D72) -> 389
A76: Legend
A77: White cells | B77: Computed directly from the timetable PDF (route length, frequency range, buses currently allocated).
A78: Yellow cells | B78: Estimated under a stated assumption — τ_r assumes an average operating speed of 22 km/h (typical mixed urban traffic for Chandigarh; not a measured value). Adjust B3-style formula input if you have a better estimate.
A79: Red italic text | B79: Not derivable from this dataset. D_rt (passenger demand), C (bus capacity), and o_rt (overcrowding) require ridership data / fleet specs that aren't in the timetable — this is exactly the data-gap your synopsis Section 6 identifies.
A81: Note: T (time periods, e.g. morning peak / midday off-peak) is not split here because the timetable gives only a single all-day frequency band per route, not per-period frequencies. f_rt^min/f_rt^max above are the operational bounds implied by the published 'X-Y min' frequency range, not distinct AM/PM values.

Sheet Network Summary
A1: Metric | B1: Value
A2: Total Routes (Depot II, III, IV combined) | B2: 68
A3: Total Buses Deployed Across All Routes | B3: 389
A4: Total Route Network Length (km, sum of all routes) | B4: 1662
A5: Average Route Length (km) | B5: 24.44
A6: Average Buses per Route | B6: 5.72
A7: Unique Stops / Landmarks Identified | B7: 649
A9: Top 10 Busiest Interchange Points (by number of routes serving)
A10: Stop / Landmark | B10: Routes Serving It
A11: ISBT-17 | B11: 47
A12: ISBT-43 | B12: 39
A13: PGI | B13: 33
A14: Aroma | B14: 22
A15: 23/22 | B15: 18
A16: PEC | B16: 16
A17: New OPD | B17: 12
A18: Attawa | B18: 12
A19: 10/16 | B19: 10
A20: 7/19 | B20: 10
A22: Data source
A23: CTU Time Table of CTU Bus Services, Local & Tri-City Routes, Depot Nos. II, III & IV, as on 25.07.2026 (chdctu.gov.in)
A24: Route Master checked against this PDF on 15 Oct 2026: see sheet "PDF Verification"

Sheet Operating Windows
A1: Period definitions (assumption, editable)
A2: AM peak | B2: 0.29166667 | C2: 0.41666667 | D2: Start / End in columns B / C. These are modelling assumptions (not from the PDF) used only for the active-period flags below.
A3: Midday | B3: 0.41666667 | C3: 0.66666667 | D3: Source of windows: CTU Time Table of Local & Tri-City Routes, Depots II, III & IV, as on 25.07.2026.
A4: PM peak | B4: 0.66666667 | C4: 0.79166667
A6: Route No. | B6: Direction A | C6: A first | D6: A last | E6: Direction B | F6: B first | G6: B last | H6: First departure | I6: Last departure | J6: Daily span (hrs) | K6: Service type | L6: Active AM | M6: Active Midday | N6: Active PM | O6: Notes
A7: 1 | B7: New Maloya Colony to Manimajra | C7: 0.25694444 | D7: 0.72222222 | E7: Manimajra to New Maloya Colony | F7: 0.3125 | G7: 0.77777778 | H7: =MIN(C7,F7) -> 0.25694444 | I7: =MAX(D7,G7) -> 0.77777778 | J7: =IF(I7<H7,(I7+1-H7)*24,(I7-H7)*24) -> 12.5 | K7: Day service | L7: =IF(AND(H7<$C$2,IF(I7<H7,I7+1,I7)>$B$2),1,0) -> 1 | M7: =IF(AND(H7<$C$3,IF(I7<H7,I7+1,I7)>$B$3),1,0) -> 1 | N7: =IF(AND(H7<$C$4,IF(I7<H7,I7+1,I7)>$B$4),1,0) -> 1
A8: 2A | B8: Loop (single direction) | C8: 0.23611111 | D8: 0.85416667 | H8: =MIN(C8,F8) -> 0.23611111 | I8: =MAX(D8,G8) -> 0.85416667 | J8: =IF(I8<H8,(I8+1-H8)*24,(I8-H8)*24) -> 14.833333 | K8: Day service | L8: =IF(AND(H8<$C$2,IF(I8<H8,I8+1,I8)>$B$2),1,0) -> 1 | M8: =IF(AND(H8<$C$3,IF(I8<H8,I8+1,I8)>$B$3),1,0) -> 1 | N8: =IF(AND(H8<$C$4,IF(I8<H8,I8+1,I8)>$B$4),1,0) -> 1
A9: 2C | B9: Loop (single direction) | C9: 0.22916667 | D9: 0.84722222 | H9: =MIN(C9,F9) -> 0.22916667 | I9: =MAX(D9,G9) -> 0.84722222 | J9: =IF(I9<H9,(I9+1-H9)*24,(I9-H9)*24) -> 14.833333 | K9: Day service | L9: =IF(AND(H9<$C$2,IF(I9<H9,I9+1,I9)>$B$2),1,0) -> 1 | M9: =IF(AND(H9<$C$3,IF(I9<H9,I9+1,I9)>$B$3),1,0) -> 1 | N9: =IF(AND(H9<$C$4,IF(I9<H9,I9+1,I9)>$B$4),1,0) -> 1
A10: 4A | B10: Loop (single direction) | C10: 0.28125 | D10: 0.81944444 | H10: =MIN(C10,F10) -> 0.28125 | I10: =MAX(D10,G10) -> 0.81944444 | J10: =IF(I10<H10,(I10+1-H10)*24,(I10-H10)*24) -> 12.916667 | K10: Day service | L10: =IF(AND(H10<$C$2,IF(I10<H10,I10+1,I10)>$B$2),1,0) -> 1 | M10: =IF(AND(H10<$C$3,IF(I10<H10,I10+1,I10)>$B$3),1,0) -> 1 | N10: =IF(AND(H10<$C$4,IF(I10<H10,I10+1,I10)>$B$4),1,0) -> 1
A11: 4C | B11: Loop (single direction) | C11: 0.30902778 | D11: 0.84722222 | H11: =MIN(C11,F11) -> 0.30902778 | I11: =MAX(D11,G11) -> 0.84722222 | J11: =IF(I11<H11,(I11+1-H11)*24,(I11-H11)*24) -> 12.916667 | K11: Day service | L11: =IF(AND(H11<$C$2,IF(I11<H11,I11+1,I11)>$B$2),1,0) -> 1 | M11: =IF(AND(H11<$C$3,IF(I11<H11,I11+1,I11)>$B$3),1,0) -> 1 | N11: =IF(AND(H11<$C$4,IF(I11<H11,I11+1,I11)>$B$4),1,0) -> 1
A12: 5A | B12: Loop (single direction) | C12: 0.22569444 | D12: 0.875 | H12: =MIN(C12,F12) -> 0.22569444 | I12: =MAX(D12,G12) -> 0.875 | J12: =IF(I12<H12,(I12+1-H12)*24,(I12-H12)*24) -> 15.583333 | K12: Day service | L12: =IF(AND(H12<$C$2,IF(I12<H12,I12+1,I12)>$B$2),1,0) -> 1 | M12: =IF(AND(H12<$C$3,IF(I12<H12,I12+1,I12)>$B$3),1,0) -> 1 | N12: =IF(AND(H12<$C$4,IF(I12<H12,I12+1,I12)>$B$4),1,0) -> 1 | O12: First trip 05.25 from ISBT-43 to Ram Darbar; regular service from 05.45.
A13: 5C | B13: Loop (single direction) | C13: 0.24305556 | D13: 0.89236111 | H13: =MIN(C13,F13) -> 0.24305556 | I13: =MAX(D13,G13) -> 0.89236111 | J13: =IF(I13<H13,(I13+1-H13)*24,(I13-H13)*24) -> 15.583333 | K13: Day service | L13: =IF(AND(H13<$C$2,IF(I13<H13,I13+1,I13)>$B$2),1,0) -> 1 | M13: =IF(AND(H13<$C$3,IF(I13<H13,I13+1,I13)>$B$3),1,0) -> 1 | N13: =IF(AND(H13<$C$4,IF(I13<H13,I13+1,I13)>$B$4),1,0) -> 1 | O13: First trip 05.50 from ISBT-43 to Ram Darbar; regular service from 06.10 (window shown starts 05.50).
A14: 6 | B14: New Maloya Colony to Raipur Kalan | C14: 0.20833333 | D14: 0.71527778 | E14: Raipur Kalan to New Maloya Colony | F14: 0.27083333 | G14: 0.77777778 | H14: =MIN(C14,F14) -> 0.20833333 | I14: =MAX(D14,G14) -> 0.77777778 | J14: =IF(I14<H14,(I14+1-H14)*24,(I14-H14)*24) -> 13.666667 | K14: Day service | L14: =IF(AND(H14<$C$2,IF(I14<H14,I14+1,I14)>$B$2),1,0) -> 1 | M14: =IF(AND(H14<$C$3,IF(I14<H14,I14+1,I14)>$B$3),1,0) -> 1 | N14: =IF(AND(H14<$C$4,IF(I14<H14,I14+1,I14)>$B$4),1,0) -> 1
A15: 7 | B15: New Maloya Colony to Ramdarbar | C15: 0.23958333 | D15: 0.77777778 | E15: Ramdarbar to New Maloya Colony | F15: 0.29166667 | G15: 0.72569444 | H15: =MIN(C15,F15) -> 0.23958333 | I15: =MAX(D15,G15) -> 0.77777778 | J15: =IF(I15<H15,(I15+1-H15)*24,(I15-H15)*24) -> 12.916667 | K15: Day service | L15: =IF(AND(H15<$C$2,IF(I15<H15,I15+1,I15)>$B$2),1,0) -> 1 | M15: =IF(AND(H15<$C$3,IF(I15<H15,I15+1,I15)>$B$3),1,0) -> 1 | N15: =IF(AND(H15<$C$4,IF(I15<H15,I15+1,I15)>$B$4),1,0) -> 1
A16: 9A | B16: Loop (single direction) | C16: 0.25694444 | D16: 0.85416667 | H16: =MIN(C16,F16) -> 0.25694444 | I16: =MAX(D16,G16) -> 0.85416667 | J16: =IF(I16<H16,(I16+1-H16)*24,(I16-H16)*24) -> 14.333333 | K16: Day service | L16: =IF(AND(H16<$C$2,IF(I16<H16,I16+1,I16)>$B$2),1,0) -> 1 | M16: =IF(AND(H16<$C$3,IF(I16<H16,I16+1,I16)>$B$3),1,0) -> 1 | N16: =IF(AND(H16<$C$4,IF(I16<H16,I16+1,I16)>$B$4),1,0) -> 1
A17: 9C | B17: Loop (single direction) | C17: 0.23611111 | D17: 0.86458333 | H17: =MIN(C17,F17) -> 0.23611111 | I17: =MAX(D17,G17) -> 0.86458333 | J17: =IF(I17<H17,(I17+1-H17)*24,(I17-H17)*24) -> 15.083333 | K17: Day service | L17: =IF(AND(H17<$C$2,IF(I17<H17,I17+1,I17)>$B$2),1,0) -> 1 | M17: =IF(AND(H17<$C$3,IF(I17<H17,I17+1,I17)>$B$3),1,0) -> 1 | N17: =IF(AND(H17<$C$4,IF(I17<H17,I17+1,I17)>$B$4),1,0) -> 1 | O17: 05.40 start is from Railway Station; last trip 20.45 runs only up to Railway Station.
A18: 11A | B18: Rock Garden to Sukhna Lake | C18: 0.42361111 | D18: 0.65972222 | H18: =MIN(C18,F18) -> 0.42361111 | I18: =MAX(D18,G18) -> 0.65972222 | J18: =IF(I18<H18,(I18+1-H18)*24,(I18-H18)*24) -> 5.6666667 | K18: Tourist link (short) | L18: =IF(AND(H18<$C$2,IF(I18<H18,I18+1,I18)>$B$2),1,0) -> 0 | M18: =IF(AND(H18<$C$3,IF(I18<H18,I18+1,I18)>$B$3),1,0) -> 1 | N18: =IF(AND(H18<$C$4,IF(I18<H18,I18+1,I18)>$B$4),1,0) -> 0 | O18: PDF gives a single window for the route.
A19: 23B | B19: ISBT-17 to Badi Karoran | C19: 0.26041667 | D19: 0.82291667 | E19: Badi Karoran to ISBT-17 | F19: 0.29166667 | G19: 0.85416667 | H19: =MIN(C19,F19) -> 0.26041667 | I19: =MAX(D19,G19) -> 0.85416667 | J19: =IF(I19<H19,(I19+1-H19)*24,(I19-H19)*24) -> 14.25 | K19: Day service | L19: =IF(AND(H19<$C$2,IF(I19<H19,I19+1,I19)>$B$2),1,0) -> 1 | M19: =IF(AND(H19<$C$3,IF(I19<H19,I19+1,I19)>$B$3),1,0) -> 1 | N19: =IF(AND(H19<$C$4,IF(I19<H19,I19+1,I19)>$B$4),1,0) -> 1
A20: 28A | B20: ISBT-43 to Rani Majra | C20: 0.35069444 | D20: 0.75 | E20: Rani Majra to ISBT-43 | F20: 0.29861111 | G20: 0.80208333 | H20: =MIN(C20,F20) -> 0.29861111 | I20: =MAX(D20,G20) -> 0.80208333 | J20: =IF(I20<H20,(I20+1-H20)*24,(I20-H20)*24) -> 12.083333 | K20: Day service | L20: =IF(AND(H20<$C$2,IF(I20<H20,I20+1,I20)>$B$2),1,0) -> 1 | M20: =IF(AND(H20<$C$3,IF(I20<H20,I20+1,I20)>$B$3),1,0) -> 1 | N20: =IF(AND(H20<$C$4,IF(I20<H20,I20+1,I20)>$B$4),1,0) -> 1
A21: 28B | B21: ISBT-43 to Eco City Block-2 (Takipur) | C21: 0.26041667 | D21: 0.82291667 | E21: Eco City Block-2 (Takipur) to ISBT-43 | F21: 0.24305556 | G21: 0.875 | H21: =MIN(C21,F21) -> 0.24305556 | I21: =MAX(D21,G21) -> 0.875 | J21: =IF(I21<H21,(I21+1-H21)*24,(I21-H21)*24) -> 15.166667 | K21: Day service | L21: =IF(AND(H21<$C$2,IF(I21<H21,I21+1,I21)>$B$2),1,0) -> 1 | M21: =IF(AND(H21<$C$3,IF(I21<H21,I21+1,I21)>$B$3),1,0) -> 1 | N21: =IF(AND(H21<$C$4,IF(I21<H21,I21+1,I21)>$B$4),1,0) -> 1
A22: 239 | B22: ISBT-43 to Lake | C22: 0.30555556 | D22: 0.80902778 | E22: Lake to ISBT-43 | F22: 0.35416667 | G22: 0.84375 | H22: =MIN(C22,F22) -> 0.30555556 | I22: =MAX(D22,G22) -> 0.84375 | J22: =IF(I22<H22,(I22+1-H22)*24,(I22-H22)*24) -> 12.916667 | K22: Day service | L22: =IF(AND(H22<$C$2,IF(I22<H22,I22+1,I22)>$B$2),1,0) -> 1 | M22: =IF(AND(H22<$C$3,IF(I22<H22,I22+1,I22)>$B$3),1,0) -> 1 | N22: =IF(AND(H22<$C$4,IF(I22<H22,I22+1,I22)>$B$4),1,0) -> 1
A23: 70A | B23: Jayanti Majri to Mansa Devi | C23: 0.22916667 | D23: 0.76041667 | E23: Mansa Devi to Jayanti Majri | F23: 0.32291667 | G23: 0.82291667 | H23: =MIN(C23,F23) -> 0.22916667 | I23: =MAX(D23,G23) -> 0.82291667 | J23: =IF(I23<H23,(I23+1-H23)*24,(I23-H23)*24) -> 14.25 | K23: Day service | L23: =IF(AND(H23<$C$2,IF(I23<H23,I23+1,I23)>$B$2),1,0) -> 1 | M23: =IF(AND(H23<$C$3,IF(I23<H23,I23+1,I23)>$B$3),1,0) -> 1 | N23: =IF(AND(H23<$C$4,IF(I23<H23,I23+1,I23)>$B$4),1,0) -> 1 | O23: First Jayanti Majri trip 05.30 starts at S.P. Barrier; last 18.15 trip runs only up to ISBT-17.
A24: 2F | B24: PGI to Platinum Homes | C24: 0.23611111 | D24: 0.76388889 | E24: Platinum Homes to PGI | F24: 0.26388889 | G24: 0.78472222 | H24: =MIN(C24,F24) -> 0.23611111 | I24: =MAX(D24,G24) -> 0.78472222 | J24: =IF(I24<H24,(I24+1-H24)*24,(I24-H24)*24) -> 13.166667 | K24: Day service | L24: =IF(AND(H24<$C$2,IF(I24<H24,I24+1,I24)>$B$2),1,0) -> 1 | M24: =IF(AND(H24<$C$3,IF(I24<H24,I24+1,I24)>$B$3),1,0) -> 1 | N24: =IF(AND(H24<$C$4,IF(I24<H24,I24+1,I24)>$B$4),1,0) -> 1
A25: 2G | B25: PGI to Panchkula Bus Stand | C25: 0.35416667 | D25: 0.59722222 | E25: Panchkula Bus Stand to PGI | F25: 0.35416667 | G25: 0.59722222 | H25: =MIN(C25,F25) -> 0.35416667 | I25: =MAX(D25,G25) -> 0.59722222 | J25: =IF(I25<H25,(I25+1-H25)*24,(I25-H25)*24) -> 5.8333333 | K25: Day service | L25: =IF(AND(H25<$C$2,IF(I25<H25,I25+1,I25)>$B$2),1,0) -> 1 | M25: =IF(AND(H25<$C$3,IF(I25<H25,I25+1,I25)>$B$3),1,0) -> 1 | N25: =IF(AND(H25<$C$4,IF(I25<H25,I25+1,I25)>$B$4),1,0) -> 0 | O25: Same window printed for both directions.
A26: 8 | B26: Mohali Ph-XI to PGI | C26: 0.25347222 | D26: 0.86805556 | H26: =MIN(C26,F26) -> 0.25347222 | I26: =MAX(D26,G26) -> 0.86805556 | J26: =IF(I26<H26,(I26+1-H26)*24,(I26-H26)*24) -> 14.75 | K26: Day service | L26: =IF(AND(H26<$C$2,IF(I26<H26,I26+1,I26)>$B$2),1,0) -> 1 | M26: =IF(AND(H26<$C$3,IF(I26<H26,I26+1,I26)>$B$3),1,0) -> 1 | N26: =IF(AND(H26<$C$4,IF(I26<H26,I26+1,I26)>$B$4),1,0) -> 1 | O26: PDF gives a single window for the route.
A27: 10 | B27: ISBT-43 to Manimajra | C27: 0.22916667 | D27: 0.73263889 | E27: Manimajra to ISBT-43 | F27: 0.27777778 | G27: 0.78125 | H27: =MIN(C27,F27) -> 0.22916667 | I27: =MAX(D27,G27) -> 0.78125 | J27: =IF(I27<H27,(I27+1-H27)*24,(I27-H27)*24) -> 13.25 | K27: Day service | L27: =IF(AND(H27<$C$2,IF(I27<H27,I27+1,I27)>$B$2),1,0) -> 1 | M27: =IF(AND(H27<$C$3,IF(I27<H27,I27+1,I27)>$B$3),1,0) -> 1 | N27: =IF(AND(H27<$C$4,IF(I27<H27,I27+1,I27)>$B$4),1,0) -> 1
A28: 11 | B28: Railway Station to CIVIL SECTT. | C28: 0.35763889 | D28: 0.69444444 | H28: =MIN(C28,F28) -> 0.35763889 | I28: =MAX(D28,G28) -> 0.69444444 | J28: =IF(I28<H28,(I28+1-H28)*24,(I28-H28)*24) -> 8.0833333 | K28: Day service | L28: =IF(AND(H28<$C$2,IF(I28<H28,I28+1,I28)>$B$2),1,0) -> 1 | M28: =IF(AND(H28<$C$3,IF(I28<H28,I28+1,I28)>$B$3),1,0) -> 1 | N28: =IF(AND(H28<$C$4,IF(I28<H28,I28+1,I28)>$B$4),1,0) -> 1 | O28: PDF gives a single window for the route.
A29: 17 | B29: ISBT-43 to Behlana | C29: 0.23611111 | D29: 0.82638889 | E29: Behlana to ISBT-43 | F29: 0.27777778 | G29: 0.86111111 | H29: =MIN(C29,F29) -> 0.23611111 | I29: =MAX(D29,G29) -> 0.86111111 | J29: =IF(I29<H29,(I29+1-H29)*24,(I29-H29)*24) -> 15 | K29: Day service | L29: =IF(AND(H29<$C$2,IF(I29<H29,I29+1,I29)>$B$2),1,0) -> 1 | M29: =IF(AND(H29<$C$3,IF(I29<H29,I29+1,I29)>$B$3),1,0) -> 1 | N29: =IF(AND(H29<$C$4,IF(I29<H29,I29+1,I29)>$B$4),1,0) -> 1
A30: 18 | B30: ISBT-43 to Kaimbwala | C30: 0.25694444 | D30: 0.80208333 | E30: Kaimbwala to ISBT-43 | F30: 0.26041667 | G30: 0.84375 | H30: =MIN(C30,F30) -> 0.25694444 | I30: =MAX(D30,G30) -> 0.84375 | J30: =IF(I30<H30,(I30+1-H30)*24,(I30-H30)*24) -> 14.083333 | K30: Day service | L30: =IF(AND(H30<$C$2,IF(I30<H30,I30+1,I30)>$B$2),1,0) -> 1 | M30: =IF(AND(H30<$C$3,IF(I30<H30,I30+1,I30)>$B$3),1,0) -> 1 | N30: =IF(AND(H30<$C$4,IF(I30<H30,I30+1,I30)>$B$4),1,0) -> 1
A31: 14 | B31: ISBT-43 to Mansa Devi | C31: 0.35416667 | D31: 0.60416667 | E31: Mansa Devi to ISBT-43 | F31: 0.35416667 | G31: 0.60416667 | H31: =MIN(C31,F31) -> 0.35416667 | I31: =MAX(D31,G31) -> 0.60416667 | J31: =IF(I31<H31,(I31+1-H31)*24,(I31-H31)*24) -> 6 | K31: Day service | L31: =IF(AND(H31<$C$2,IF(I31<H31,I31+1,I31)>$B$2),1,0) -> 1 | M31: =IF(AND(H31<$C$3,IF(I31<H31,I31+1,I31)>$B$3),1,0) -> 1 | N31: =IF(AND(H31<$C$4,IF(I31<H31,I31+1,I31)>$B$4),1,0) -> 0 | O31: Same window printed for both directions.
A32: 20 | B32: CHD to Kharar | C32: 0.22916667 | D32: 0.83333333 | E32: Kharar to CHD | F32: 0.28125 | G32: 0.86458333 | H32: =MIN(C32,F32) -> 0.22916667 | I32: =MAX(D32,G32) -> 0.86458333 | J32: =IF(I32<H32,(I32+1-H32)*24,(I32-H32)*24) -> 15.25 | K32: Day service | L32: =IF(AND(H32<$C$2,IF(I32<H32,I32+1,I32)>$B$2),1,0) -> 1 | M32: =IF(AND(H32<$C$3,IF(I32<H32,I32+1,I32)>$B$3),1,0) -> 1 | N32: =IF(AND(H32<$C$4,IF(I32<H32,I32+1,I32)>$B$4),1,0) -> 1 | O32: Extra fixed trips not in windows: ISBT-17 to ISBT-43 at 05.45, 06.45, 07.45; Kharar to ISBT-43 at 19.00, 19.30, 20.00, 20.30, 21.00, 21.20.
A33: 20A | B33: CHD to Kharar | C33: 0.32291667 | D33: 0.78125 | E33: Kharar to CHD | F33: 0.26041667 | G33: 0.84375 | H33: =MIN(C33,F33) -> 0.26041667 | I33: =MAX(D33,G33) -> 0.84375 | J33: =IF(I33<H33,(I33+1-H33)*24,(I33-H33)*24) -> 14 | K33: Day service | L33: =IF(AND(H33<$C$2,IF(I33<H33,I33+1,I33)>$B$2),1,0) -> 1 | M33: =IF(AND(H33<$C$3,IF(I33<H33,I33+1,I33)>$B$3),1,0) -> 1 | N33: =IF(AND(H33<$C$4,IF(I33<H33,I33+1,I33)>$B$4),1,0) -> 1
A34: 22 | B34: ISBT-43 to IT Park | C34: 0.23611111 | D34: 0.80555556 | E34: IT Park to ISBT-43 | F34: 0.28472222 | G34: 0.85416667 | H34: =MIN(C34,F34) -> 0.23611111 | I34: =MAX(D34,G34) -> 0.85416667 | J34: =IF(I34<H34,(I34+1-H34)*24,(I34-H34)*24) -> 14.833333 | K34: Day service | L34: =IF(AND(H34<$C$2,IF(I34<H34,I34+1,I34)>$B$2),1,0) -> 1 | M34: =IF(AND(H34<$C$3,IF(I34<H34,I34+1,I34)>$B$3),1,0) -> 1 | N34: =IF(AND(H34<$C$4,IF(I34<H34,I34+1,I34)>$B$4),1,0) -> 1
A35: 23A | B35: ISBT-43 to Khuda Ali Sher | C35: 0.22916667 | D35: 0.81944444 | E35: Khuda Ali Sher to ISBT-43 | F35: 0.27083333 | G35: 0.86111111 | H35: =MIN(C35,F35) -> 0.22916667 | I35: =MAX(D35,G35) -> 0.86111111 | J35: =IF(I35<H35,(I35+1-H35)*24,(I35-H35)*24) -> 15.166667 | K35: Day service | L35: =IF(AND(H35<$C$2,IF(I35<H35,I35+1,I35)>$B$2),1,0) -> 1 | M35: =IF(AND(H35<$C$3,IF(I35<H35,I35+1,I35)>$B$3),1,0) -> 1 | N35: =IF(AND(H35<$C$4,IF(I35<H35,I35+1,I35)>$B$4),1,0) -> 1
A36: 24A | B36: ISBT-43 to PGI | C36: 0.91666667 | D36: 0.19444444 | H36: =MIN(C36,F36) -> 0.91666667 | I36: =MAX(D36,G36) -> 0.19444444 | J36: =IF(I36<H36,(I36+1-H36)*24,(I36-H36)*24) -> 6.6666667 | K36: Night service | L36: =IF(AND(H36<$C$2,IF(I36<H36,I36+1,I36)>$B$2),1,0) -> 0 | M36: =IF(AND(H36<$C$3,IF(I36<H36,I36+1,I36)>$B$3),1,0) -> 0 | N36: =IF(AND(H36<$C$4,IF(I36<H36,I36+1,I36)>$B$4),1,0) -> 0
A37: 24C | B37: ISBT-17 to ISBT-43 | C37: 0.92708333 | D37: 0.22222222 | H37: =MIN(C37,F37) -> 0.92708333 | I37: =MAX(D37,G37) -> 0.22222222 | J37: =IF(I37<H37,(I37+1-H37)*24,(I37-H37)*24) -> 7.0833333 | K37: Night service | L37: =IF(AND(H37<$C$2,IF(I37<H37,I37+1,I37)>$B$2),1,0) -> 0 | M37: =IF(AND(H37<$C$3,IF(I37<H37,I37+1,I37)>$B$3),1,0) -> 0 | N37: =IF(AND(H37<$C$4,IF(I37<H37,I37+1,I37)>$B$4),1,0) -> 0
A38: 26 | B38: Mullanpur Eco City to Dhakoli | C38: 0.25 | D38: 0.80902778 | E38: Dhakoli to Mullanpur Eco City | F38: 0.25 | G38: 0.78472222 | H38: =MIN(C38,F38) -> 0.25 | I38: =MAX(D38,G38) -> 0.80902778 | J38: =IF(I38<H38,(I38+1-H38)*24,(I38-H38)*24) -> 13.416667 | K38: Day service | L38: =IF(AND(H38<$C$2,IF(I38<H38,I38+1,I38)>$B$2),1,0) -> 1 | M38: =IF(AND(H38<$C$3,IF(I38<H38,I38+1,I38)>$B$3),1,0) -> 1 | N38: =IF(AND(H38<$C$4,IF(I38<H38,I38+1,I38)>$B$4),1,0) -> 1
A39: 28 | B39: New Maloya Colony to Manimajra | C39: 0.26041667 | D39: 0.77083333 | E39: Manimajra to New Maloya Colony | F39: 0.32291667 | G39: 0.83333333 | H39: =MIN(C39,F39) -> 0.26041667 | I39: =MAX(D39,G39) -> 0.83333333 | J39: =IF(I39<H39,(I39+1-H39)*24,(I39-H39)*24) -> 13.75 | K39: Day service | L39: =IF(AND(H39<$C$2,IF(I39<H39,I39+1,I39)>$B$2),1,0) -> 1 | M39: =IF(AND(H39<$C$3,IF(I39<H39,I39+1,I39)>$B$3),1,0) -> 1 | N39: =IF(AND(H39<$C$4,IF(I39<H39,I39+1,I39)>$B$4),1,0) -> 1
A40: 30 | B40: ISBT-43 to Nada Sahib | C40: 0.27430556 | D40: 0.82986111 | E40: Nada Sahib to ISBT-43 | F40: 0.25347222 | G40: 0.82986111 | H40: =MIN(C40,F40) -> 0.25347222 | I40: =MAX(D40,G40) -> 0.82986111 | J40: =IF(I40<H40,(I40+1-H40)*24,(I40-H40)*24) -> 13.833333 | K40: Day service | L40: =IF(AND(H40<$C$2,IF(I40<H40,I40+1,I40)>$B$2),1,0) -> 1 | M40: =IF(AND(H40<$C$3,IF(I40<H40,I40+1,I40)>$B$3),1,0) -> 1 | N40: =IF(AND(H40<$C$4,IF(I40<H40,I40+1,I40)>$B$4),1,0) -> 1
A41: 30A | B41: ISBT-43 to Cantonment | C41: 0.21527778 | D41: 0.82291667 | E41: Cantonment to ISBT-43 | F41: 0.26736111 | G41: 0.875 | H41: =MIN(C41,F41) -> 0.21527778 | I41: =MAX(D41,G41) -> 0.875 | J41: =IF(I41<H41,(I41+1-H41)*24,(I41-H41)*24) -> 15.833333 | K41: Day service | L41: =IF(AND(H41<$C$2,IF(I41<H41,I41+1,I41)>$B$2),1,0) -> 1 | M41: =IF(AND(H41<$C$3,IF(I41<H41,I41+1,I41)>$B$3),1,0) -> 1 | N41: =IF(AND(H41<$C$4,IF(I41<H41,I41+1,I41)>$B$4),1,0) -> 1
...

Sheet PDF Verification
A1: Verification of Route Master against CTU timetable PDF (as on 25.07.2026)
A2: Routes in PDF | C2: =COUNTA(A9:A76) -> 68
A3: Routes matching on frequency, length and buses | C3: =COUNTIF(H9:H76,"OK") -> 68
A4: Buses in PDF (sum) | C4: =SUM(D9:D76) -> 389
A5: Buses in Route Master (TOTAL row) | C5: ='Route Master'!I70 -> 389
A6: Route length in PDF (km, sum) | C6: =SUM(C9:C76) -> 1662
A7: Route length in Route Master (km, TOTAL row) | C7: ='Route Master'!H70 -> 1662
A8: Route No. | B8: PDF frequency (min) | C8: PDF length (km) | D8: PDF buses | E8: Workbook frequency (min) | F8: Workbook length (km) | G8: Workbook buses | H8: Match
A9: 1 | B9: 20 | C9: 24 | D9: 8 | E9: =INDEX('Route Master'!$E$2:$E$69,MATCH(A9,'Route Master'!$A$2:$A$69,0)) -> 20 | F9: =INDEX('Route Master'!$H$2:$H$69,MATCH(A9,'Route Master'!$A$2:$A$69,0)) -> 24 | G9: =INDEX('Route Master'!$I$2:$I$69,MATCH(A9,'Route Master'!$A$2:$A$69,0)) -> 8 | H9: =IF(AND(B9=E9,C9=F9,D9=G9),"OK","CHECK") -> OK
A10: 2A | B10: 20-25 | C10: 38.3 | D10: 6 | E10: =INDEX('Route Master'!$E$2:$E$69,MATCH(A10,'Route Master'!$A$2:$A$69,0)) -> 20-25 | F10: =INDEX('Route Master'!$H$2:$H$69,MATCH(A10,'Route Master'!$A$2:$A$69,0)) -> 38.3 | G10: =INDEX('Route Master'!$I$2:$I$69,MATCH(A10,'Route Master'!$A$2:$A$69,0)) -> 6 | H10: =IF(AND(B10=E10,C10=F10,D10=G10),"OK","CHECK") -> OK
A11: 2C | B11: 20-25 | C11: 38.3 | D11: 6 | E11: =INDEX('Route Master'!$E$2:$E$69,MATCH(A11,'Route Master'!$A$2:$A$69,0)) -> 20-25 | F11: =INDEX('Route Master'!$H$2:$H$69,MATCH(A11,'Route Master'!$A$2:$A$69,0)) -> 38.3 | G11: =INDEX('Route Master'!$I$2:$I$69,MATCH(A11,'Route Master'!$A$2:$A$69,0)) -> 6 | H11: =IF(AND(B11=E11,C11=F11,D11=G11),"OK","CHECK") -> OK
A12: 4A | B12: 25 | C12: 32.5 | D12: 4 | E12: =INDEX('Route Master'!$E$2:$E$69,MATCH(A12,'Route Master'!$A$2:$A$69,0)) -> 25 | F12: =INDEX('Route Master'!$H$2:$H$69,MATCH(A12,'Route Master'!$A$2:$A$69,0)) -> 32.5 | G12: =INDEX('Route Master'!$I$2:$I$69,MATCH(A12,'Route Master'!$A$2:$A$69,0)) -> 4 | H12: =IF(AND(B12=E12,C12=F12,D12=G12),"OK","CHECK") -> OK
A13: 4C | B13: 25 | C13: 32.5 | D13: 4 | E13: =INDEX('Route Master'!$E$2:$E$69,MATCH(A13,'Route Master'!$A$2:$A$69,0)) -> 25 | F13: =INDEX('Route Master'!$H$2:$H$69,MATCH(A13,'Route Master'!$A$2:$A$69,0)) -> 32.5 | G13: =INDEX('Route Master'!$I$2:$I$69,MATCH(A13,'Route Master'!$A$2:$A$69,0)) -> 4 | H13: =IF(AND(B13=E13,C13=F13,D13=G13),"OK","CHECK") -> OK
A14: 5A | B14: 15-30 | C14: 38.4 | D14: 8 | E14: =INDEX('Route Master'!$E$2:$E$69,MATCH(A14,'Route Master'!$A$2:$A$69,0)) -> 15-30 | F14: =INDEX('Route Master'!$H$2:$H$69,MATCH(A14,'Route Master'!$A$2:$A$69,0)) -> 38.4 | G14: =INDEX('Route Master'!$I$2:$I$69,MATCH(A14,'Route Master'!$A$2:$A$69,0)) -> 8 | H14: =IF(AND(B14=E14,C14=F14,D14=G14),"OK","CHECK") -> OK
A15: 5C | B15: 15-30 | C15: 38.4 | D15: 8 | E15: =INDEX('Route Master'!$E$2:$E$69,MATCH(A15,'Route Master'!$A$2:$A$69,0)) -> 15-30 | F15: =INDEX('Route Master'!$H$2:$H$69,MATCH(A15,'Route Master'!$A$2:$A$69,0)) -> 38.4 | G15: =INDEX('Route Master'!$I$2:$I$69,MATCH(A15,'Route Master'!$A$2:$A$69,0)) -> 8 | H15: =IF(AND(B15=E15,C15=F15,D15=G15),"OK","CHECK") -> OK
A16: 6 | B16: 30 | C16: 25.5 | D16: 6 | E16: =INDEX('Route Master'!$E$2:$E$69,MATCH(A16,'Route Master'!$A$2:$A$69,0)) -> 30 | F16: =INDEX('Route Master'!$H$2:$H$69,MATCH(A16,'Route Master'!$A$2:$A$69,0)) -> 25.5 | G16: =INDEX('Route Master'!$I$2:$I$69,MATCH(A16,'Route Master'!$A$2:$A$69,0)) -> 6 | H16: =IF(AND(B16=E16,C16=F16,D16=G16),"OK","CHECK") -> OK
A17: 7 | B17: 25 | C17: 21.5 | D17: 6 | E17: =INDEX('Route Master'!$E$2:$E$69,MATCH(A17,'Route Master'!$A$2:$A$69,0)) -> 25 | F17: =INDEX('Route Master'!$H$2:$H$69,MATCH(A17,'Route Master'!$A$2:$A$69,0)) -> 21.5 | G17: =INDEX('Route Master'!$I$2:$I$69,MATCH(A17,'Route Master'!$A$2:$A$69,0)) -> 6 | H17: =IF(AND(B17=E17,C17=F17,D17=G17),"OK","CHECK") -> OK
A18: 9A | B18: 30 | C18: 38.3 | D18: 4 | E18: =INDEX('Route Master'!$E$2:$E$69,MATCH(A18,'Route Master'!$A$2:$A$69,0)) -> 30 | F18: =INDEX('Route Master'!$H$2:$H$69,MATCH(A18,'Route Master'!$A$2:$A$69,0)) -> 38.3 | G18: =INDEX('Route Master'!$I$2:$I$69,MATCH(A18,'Route Master'!$A$2:$A$69,0)) -> 4 | H18: =IF(AND(B18=E18,C18=F18,D18=G18),"OK","CHECK") -> OK
A19: 9C | B19: 30 | C19: 38.3 | D19: 4 | E19: =INDEX('Route Master'!$E$2:$E$69,MATCH(A19,'Route Master'!$A$2:$A$69,0)) -> 30 | F19: =INDEX('Route Master'!$H$2:$H$69,MATCH(A19,'Route Master'!$A$2:$A$69,0)) -> 38.3 | G19: =INDEX('Route Master'!$I$2:$I$69,MATCH(A19,'Route Master'!$A$2:$A$69,0)) -> 4 | H19: =IF(AND(B19=E19,C19=F19,D19=G19),"OK","CHECK") -> OK
A20: 11A | B20: 30 | C20: 3 | D20: 1 | E20: =INDEX('Route Master'!$E$2:$E$69,MATCH(A20,'Route Master'!$A$2:$A$69,0)) -> 30 | F20: =INDEX('Route Master'!$H$2:$H$69,MATCH(A20,'Route Master'!$A$2:$A$69,0)) -> 3 | G20: =INDEX('Route Master'!$I$2:$I$69,MATCH(A20,'Route Master'!$A$2:$A$69,0)) -> 1 | H20: =IF(AND(B20=E20,C20=F20,D20=G20),"OK","CHECK") -> OK
... A76: 38AB | B76: 20-25 | C76: 22 | D76: 8 | E76: =INDEX('Route Master'!$E$2:$E$69,MATCH(A76,'Route Master'!$A$2:$A$69,0)) -> 20-25 | F76: =INDEX('Route Master'!$H$2:$H$69,MATCH(A76,'Route Master'!$A$2:$A$69,0)) -> 22 | G76: =INDEX('Route Master'!$I$2:$I$69,MATCH(A76,'Route Master'!$A$2:$A$69,0)) -> 8 | H76: =IF(AND(B76=E76,C76=F76,D76=G76),"OK","CHECK") -> OK
A78: Blue values were typed from the PDF table (Sr. No. 1 to 68). Workbook columns are live lookups into Route Master. Via-stop counts and Stop Coverage were not re-derived here.
